{
    "type": "error",
    "data": "Error executing verb \"create_base_entity_graph\" in create_base_entity_graph: [Errno 5] Input/output error",
    "stack": "Traceback (most recent call last):\n  File \"/home/ggg/miniconda3/envs/graphrag/lib/python3.11/asyncio/runners.py\", line 190, in run\n    return runner.run(main)\n           ^^^^^^^^^^^^^^^^\n  File \"/home/ggg/miniconda3/envs/graphrag/lib/python3.11/asyncio/runners.py\", line 118, in run\n    return self._loop.run_until_complete(task)\n           ^^^^^^^^^^^^^^^^^^^^^^^^^^^^^^^^^^^\n  File \"/home/ggg/miniconda3/envs/graphrag/lib/python3.11/asyncio/base_events.py\", line 641, in run_until_complete\n    self.run_forever()\n  File \"/home/ggg/miniconda3/envs/graphrag/lib/python3.11/asyncio/base_events.py\", line 608, in run_forever\n    self._run_once()\n  File \"/home/ggg/miniconda3/envs/graphrag/lib/python3.11/asyncio/base_events.py\", line 1898, in _run_once\n    event_list = self._selector.select(timeout)\n                 ^^^^^^^^^^^^^^^^^^^^^^^^^^^^^^\n  File \"/home/ggg/miniconda3/envs/graphrag/lib/python3.11/selectors.py\", line 468, in select\n    fd_event_list = self._selector.poll(timeout, max_ev)\n                    ^^^^^^^^^^^^^^^^^^^^^^^^^^^^^^^^^^^^\n  File \"/home/ggg/miniconda3/envs/graphrag/lib/python3.11/site-packages/graphrag/cli/index.py\", line 55, in handle_signal\n    reporter.info(f\"Received signal {signum}, exiting...\")\n  File \"/home/ggg/miniconda3/envs/graphrag/lib/python3.11/site-packages/graphrag/logging/rich_progress.py\", line 139, in info\n    self._console.print(message)\n  File \"/home/ggg/miniconda3/envs/graphrag/lib/python3.11/site-packages/rich/console.py\", line 1678, in print\n    with self:\n  File \"/home/ggg/miniconda3/envs/graphrag/lib/python3.11/site-packages/rich/console.py\", line 864, in __exit__\n    self._exit_buffer()\n  File \"/home/ggg/miniconda3/envs/graphrag/lib/python3.11/site-packages/rich/console.py\", line 822, in _exit_buffer\n    self._check_buffer()\n  File \"/home/ggg/miniconda3/envs/graphrag/lib/python3.11/site-packages/rich/console.py\", line 2019, in _check_buffer\n    self._write_buffer()\n  File \"/home/ggg/miniconda3/envs/graphrag/lib/python3.11/site-packages/rich/console.py\", line 2088, in _write_buffer\n    self.file.write(text)\nOSError: [Errno 5] Input/output error\n\nDuring handling of the above exception, another exception occurred:\n\nTraceback (most recent call last):\n  File \"/home/ggg/miniconda3/envs/graphrag/lib/python3.11/site-packages/datashaper/workflow/workflow.py\", line 415, in _execute_verb\n    result = await result\n             ^^^^^^^^^^^^\n  File \"/home/ggg/miniconda3/envs/graphrag/lib/python3.11/site-packages/graphrag/index/workflows/v1/subflows/create_base_entity_graph.py\", line 53, in create_base_entity_graph\n    output = await create_base_entity_graph_flow(\n             ^^^^^^^^^^^^^^^^^^^^^^^^^^^^^^^^^^^^\n  File \"/home/ggg/miniconda3/envs/graphrag/lib/python3.11/site-packages/graphrag/index/flows/create_base_entity_graph.py\", line 51, in create_base_entity_graph\n    entities, entity_graphs = await extract_entities(\n                              ^^^^^^^^^^^^^^^^^^^^^^^\n  File \"/home/ggg/miniconda3/envs/graphrag/lib/python3.11/site-packages/graphrag/index/operations/extract_entities/extract_entities.py\", line 138, in extract_entities\n    results = await derive_from_rows(\n              ^^^^^^^^^^^^^^^^^^^^^^^\n  File \"/home/ggg/miniconda3/envs/graphrag/lib/python3.11/site-packages/datashaper/execution/derive_from_rows.py\", line 33, in derive_from_rows\n    return await derive_from_rows_asyncio_threads(\n           ^^^^^^^^^^^^^^^^^^^^^^^^^^^^^^^^^^^^^^^\n  File \"/home/ggg/miniconda3/envs/graphrag/lib/python3.11/site-packages/datashaper/execution/derive_from_rows_asyncio_threads.py\", line 40, in derive_from_rows_asyncio_threads\n    return await derive_from_rows_base(input, transform, callbacks, gather)\n           ^^^^^^^^^^^^^^^^^^^^^^^^^^^^^^^^^^^^^^^^^^^^^^^^^^^^^^^^^^^^^^^^\n  File \"/home/ggg/miniconda3/envs/graphrag/lib/python3.11/site-packages/datashaper/execution/derive_from_rows_base.py\", line 49, in derive_from_rows_base\n    result = await gather(execute)\n             ^^^^^^^^^^^^^^^^^^^^^\n  File \"/home/ggg/miniconda3/envs/graphrag/lib/python3.11/site-packages/datashaper/execution/derive_from_rows_asyncio_threads.py\", line 38, in gather\n    return await asyncio.gather(*[execute_task(task) for task in tasks])\n           ^^^^^^^^^^^^^^^^^^^^^^^^^^^^^^^^^^^^^^^^^^^^^^^^^^^^^^^^^^^^^\n  File \"/home/ggg/miniconda3/envs/graphrag/lib/python3.11/site-packages/datashaper/execution/derive_from_rows_asyncio_threads.py\", line 36, in execute_task\n    return await thread\n           ^^^^^^^^^^^^\n  File \"/home/ggg/miniconda3/envs/graphrag/lib/python3.11/site-packages/datashaper/execution/derive_from_rows_base.py\", line 47, in execute\n    tick(1)\n  File \"/home/ggg/miniconda3/envs/graphrag/lib/python3.11/site-packages/datashaper/progress/progress_ticker.py\", line 21, in __call__\n    self._callback(\n  File \"/home/ggg/miniconda3/envs/graphrag/lib/python3.11/site-packages/datashaper/workflow/verb_callbacks/delegating_verb_callbacks.py\", line 22, in progress\n    self._workflow_callbacks.on_step_progress(self._node, progress)\n  File \"/home/ggg/miniconda3/envs/graphrag/lib/python3.11/site-packages/datashaper/workflow/workflow_callbacks/workflow_callbacks_manager.py\", line 51, in on_step_progress\n    callback.on_step_progress(node, progress)\n  File \"/home/ggg/miniconda3/envs/graphrag/lib/python3.11/site-packages/datashaper/workflow/workflow_callbacks/workflow_callbacks_manager.py\", line 51, in on_step_progress\n    callback.on_step_progress(node, progress)\n  File \"/home/ggg/miniconda3/envs/graphrag/lib/python3.11/site-packages/graphrag/callbacks/progress_workflow_callbacks.py\", line 54, in on_step_progress\n    self._latest(progress)\n  File \"/home/ggg/miniconda3/envs/graphrag/lib/python3.11/site-packages/graphrag/logging/rich_progress.py\", line 165, in __call__\n    self.refresh()\n  File \"/home/ggg/miniconda3/envs/graphrag/lib/python3.11/site-packages/graphrag/logging/rich_progress.py\", line 111, in refresh\n    self.force_refresh()\n  File \"/home/ggg/miniconda3/envs/graphrag/lib/python3.11/site-packages/graphrag/logging/rich_progress.py\", line 115, in force_refresh\n    self.live.refresh()\n  File \"/home/ggg/miniconda3/envs/graphrag/lib/python3.11/site-packages/rich/live.py\", line 246, in refresh\n    with self.console:\n  File \"/home/ggg/miniconda3/envs/graphrag/lib/python3.11/site-packages/rich/console.py\", line 864, in __exit__\n    self._exit_buffer()\n  File \"/home/ggg/miniconda3/envs/graphrag/lib/python3.11/site-packages/rich/console.py\", line 822, in _exit_buffer\n    self._check_buffer()\n  File \"/home/ggg/miniconda3/envs/graphrag/lib/python3.11/site-packages/rich/console.py\", line 2019, in _check_buffer\n    self._write_buffer()\n  File \"/home/ggg/miniconda3/envs/graphrag/lib/python3.11/site-packages/rich/console.py\", line 2088, in _write_buffer\n    self.file.write(text)\nOSError: [Errno 5] Input/output error\n",
    "source": "[Errno 5] Input/output error",
    "details": null
}
{
    "type": "error",
    "data": "Error running pipeline!",
    "stack": "Traceback (most recent call last):\n  File \"/home/ggg/miniconda3/envs/graphrag/lib/python3.11/asyncio/runners.py\", line 190, in run\n    return runner.run(main)\n           ^^^^^^^^^^^^^^^^\n  File \"/home/ggg/miniconda3/envs/graphrag/lib/python3.11/asyncio/runners.py\", line 118, in run\n    return self._loop.run_until_complete(task)\n           ^^^^^^^^^^^^^^^^^^^^^^^^^^^^^^^^^^^\n  File \"/home/ggg/miniconda3/envs/graphrag/lib/python3.11/asyncio/base_events.py\", line 641, in run_until_complete\n    self.run_forever()\n  File \"/home/ggg/miniconda3/envs/graphrag/lib/python3.11/asyncio/base_events.py\", line 608, in run_forever\n    self._run_once()\n  File \"/home/ggg/miniconda3/envs/graphrag/lib/python3.11/asyncio/base_events.py\", line 1898, in _run_once\n    event_list = self._selector.select(timeout)\n                 ^^^^^^^^^^^^^^^^^^^^^^^^^^^^^^\n  File \"/home/ggg/miniconda3/envs/graphrag/lib/python3.11/selectors.py\", line 468, in select\n    fd_event_list = self._selector.poll(timeout, max_ev)\n                    ^^^^^^^^^^^^^^^^^^^^^^^^^^^^^^^^^^^^\n  File \"/home/ggg/miniconda3/envs/graphrag/lib/python3.11/site-packages/graphrag/cli/index.py\", line 55, in handle_signal\n    reporter.info(f\"Received signal {signum}, exiting...\")\n  File \"/home/ggg/miniconda3/envs/graphrag/lib/python3.11/site-packages/graphrag/logging/rich_progress.py\", line 139, in info\n    self._console.print(message)\n  File \"/home/ggg/miniconda3/envs/graphrag/lib/python3.11/site-packages/rich/console.py\", line 1678, in print\n    with self:\n  File \"/home/ggg/miniconda3/envs/graphrag/lib/python3.11/site-packages/rich/console.py\", line 864, in __exit__\n    self._exit_buffer()\n  File \"/home/ggg/miniconda3/envs/graphrag/lib/python3.11/site-packages/rich/console.py\", line 822, in _exit_buffer\n    self._check_buffer()\n  File \"/home/ggg/miniconda3/envs/graphrag/lib/python3.11/site-packages/rich/console.py\", line 2019, in _check_buffer\n    self._write_buffer()\n  File \"/home/ggg/miniconda3/envs/graphrag/lib/python3.11/site-packages/rich/console.py\", line 2088, in _write_buffer\n    self.file.write(text)\nOSError: [Errno 5] Input/output error\n\nDuring handling of the above exception, another exception occurred:\n\nTraceback (most recent call last):\n  File \"/home/ggg/miniconda3/envs/graphrag/lib/python3.11/site-packages/graphrag/index/run/run.py\", line 274, in run_pipeline\n    result = await _process_workflow(\n             ^^^^^^^^^^^^^^^^^^^^^^^^\n  File \"/home/ggg/miniconda3/envs/graphrag/lib/python3.11/site-packages/graphrag/index/run/workflow.py\", line 105, in _process_workflow\n    result = await workflow.run(context, callbacks)\n             ^^^^^^^^^^^^^^^^^^^^^^^^^^^^^^^^^^^^^^\n  File \"/home/ggg/miniconda3/envs/graphrag/lib/python3.11/site-packages/datashaper/workflow/workflow.py\", line 369, in run\n    timing = await self._execute_verb(node, context, callbacks)\n             ^^^^^^^^^^^^^^^^^^^^^^^^^^^^^^^^^^^^^^^^^^^^^^^^^^\n  File \"/home/ggg/miniconda3/envs/graphrag/lib/python3.11/site-packages/datashaper/workflow/workflow.py\", line 415, in _execute_verb\n    result = await result\n             ^^^^^^^^^^^^\n  File \"/home/ggg/miniconda3/envs/graphrag/lib/python3.11/site-packages/graphrag/index/workflows/v1/subflows/create_base_entity_graph.py\", line 53, in create_base_entity_graph\n    output = await create_base_entity_graph_flow(\n             ^^^^^^^^^^^^^^^^^^^^^^^^^^^^^^^^^^^^\n  File \"/home/ggg/miniconda3/envs/graphrag/lib/python3.11/site-packages/graphrag/index/flows/create_base_entity_graph.py\", line 51, in create_base_entity_graph\n    entities, entity_graphs = await extract_entities(\n                              ^^^^^^^^^^^^^^^^^^^^^^^\n  File \"/home/ggg/miniconda3/envs/graphrag/lib/python3.11/site-packages/graphrag/index/operations/extract_entities/extract_entities.py\", line 138, in extract_entities\n    results = await derive_from_rows(\n              ^^^^^^^^^^^^^^^^^^^^^^^\n  File \"/home/ggg/miniconda3/envs/graphrag/lib/python3.11/site-packages/datashaper/execution/derive_from_rows.py\", line 33, in derive_from_rows\n    return await derive_from_rows_asyncio_threads(\n           ^^^^^^^^^^^^^^^^^^^^^^^^^^^^^^^^^^^^^^^\n  File \"/home/ggg/miniconda3/envs/graphrag/lib/python3.11/site-packages/datashaper/execution/derive_from_rows_asyncio_threads.py\", line 40, in derive_from_rows_asyncio_threads\n    return await derive_from_rows_base(input, transform, callbacks, gather)\n           ^^^^^^^^^^^^^^^^^^^^^^^^^^^^^^^^^^^^^^^^^^^^^^^^^^^^^^^^^^^^^^^^\n  File \"/home/ggg/miniconda3/envs/graphrag/lib/python3.11/site-packages/datashaper/execution/derive_from_rows_base.py\", line 49, in derive_from_rows_base\n    result = await gather(execute)\n             ^^^^^^^^^^^^^^^^^^^^^\n  File \"/home/ggg/miniconda3/envs/graphrag/lib/python3.11/site-packages/datashaper/execution/derive_from_rows_asyncio_threads.py\", line 38, in gather\n    return await asyncio.gather(*[execute_task(task) for task in tasks])\n           ^^^^^^^^^^^^^^^^^^^^^^^^^^^^^^^^^^^^^^^^^^^^^^^^^^^^^^^^^^^^^\n  File \"/home/ggg/miniconda3/envs/graphrag/lib/python3.11/site-packages/datashaper/execution/derive_from_rows_asyncio_threads.py\", line 36, in execute_task\n    return await thread\n           ^^^^^^^^^^^^\n  File \"/home/ggg/miniconda3/envs/graphrag/lib/python3.11/site-packages/datashaper/execution/derive_from_rows_base.py\", line 47, in execute\n    tick(1)\n  File \"/home/ggg/miniconda3/envs/graphrag/lib/python3.11/site-packages/datashaper/progress/progress_ticker.py\", line 21, in __call__\n    self._callback(\n  File \"/home/ggg/miniconda3/envs/graphrag/lib/python3.11/site-packages/datashaper/workflow/verb_callbacks/delegating_verb_callbacks.py\", line 22, in progress\n    self._workflow_callbacks.on_step_progress(self._node, progress)\n  File \"/home/ggg/miniconda3/envs/graphrag/lib/python3.11/site-packages/datashaper/workflow/workflow_callbacks/workflow_callbacks_manager.py\", line 51, in on_step_progress\n    callback.on_step_progress(node, progress)\n  File \"/home/ggg/miniconda3/envs/graphrag/lib/python3.11/site-packages/datashaper/workflow/workflow_callbacks/workflow_callbacks_manager.py\", line 51, in on_step_progress\n    callback.on_step_progress(node, progress)\n  File \"/home/ggg/miniconda3/envs/graphrag/lib/python3.11/site-packages/graphrag/callbacks/progress_workflow_callbacks.py\", line 54, in on_step_progress\n    self._latest(progress)\n  File \"/home/ggg/miniconda3/envs/graphrag/lib/python3.11/site-packages/graphrag/logging/rich_progress.py\", line 165, in __call__\n    self.refresh()\n  File \"/home/ggg/miniconda3/envs/graphrag/lib/python3.11/site-packages/graphrag/logging/rich_progress.py\", line 111, in refresh\n    self.force_refresh()\n  File \"/home/ggg/miniconda3/envs/graphrag/lib/python3.11/site-packages/graphrag/logging/rich_progress.py\", line 115, in force_refresh\n    self.live.refresh()\n  File \"/home/ggg/miniconda3/envs/graphrag/lib/python3.11/site-packages/rich/live.py\", line 246, in refresh\n    with self.console:\n  File \"/home/ggg/miniconda3/envs/graphrag/lib/python3.11/site-packages/rich/console.py\", line 864, in __exit__\n    self._exit_buffer()\n  File \"/home/ggg/miniconda3/envs/graphrag/lib/python3.11/site-packages/rich/console.py\", line 822, in _exit_buffer\n    self._check_buffer()\n  File \"/home/ggg/miniconda3/envs/graphrag/lib/python3.11/site-packages/rich/console.py\", line 2019, in _check_buffer\n    self._write_buffer()\n  File \"/home/ggg/miniconda3/envs/graphrag/lib/python3.11/site-packages/rich/console.py\", line 2088, in _write_buffer\n    self.file.write(text)\nOSError: [Errno 5] Input/output error\n",
    "source": "[Errno 5] Input/output error",
    "details": null
}
